Workbook

Sheet 1850 Not Stated Clean
A1: Line Number | B1: Dwelling Number | C1: Family Number | D1: Given Name | E1: Surname | F1: Age | G1: Birth Date | H1: Gender | I1: Race | J1: Occupation | K1: Industry | L1: Value of Real Estate | M1: Birth Place | N1: Married within the Year | O1: Attended School | P1: Cannot Read, Write | Q1: Condition
A2: 1 | B2: 1 | C2: 1 | D2: Sherman | E2: Reynolds | F2: 34 | G2: 1816 | H2: Male | I2: White | J2: Merchant | L2: 10160 | M2: New York
A3: 2 | B3: 1 | C3: 1 | D3: Martha | E3: Reynolds | F3: 22 | G3: 1828 | H3: Female | I3: White | M3: Illinois
A4: 3 | B4: 1 | C4: 1 | D4: Albert B | E4: Reynolds | F4: 2 | G4: 1848 | H4: Male | I4: White | M4: Texas
A5: 4 | B5: 2 | C5: 2 | D5: Sherman A | E5: Reynolds | F5: 5/12 | G5: 1850 | H5: Male | I5: White | M5: Texas
A6: 5 | B6: 2 | C6: 2 | D6: H M | E6: Lawhon | F6: 45 | G6: 1805 | H6: Male | I6: White | J6: Farmer | K6: Agriculture | L6: 300 | M6: North Carolina
A7: 6 | B7: 2 | C7: 2 | D7: Anna | E7: Lawhon | F7: 44 | G7: 1806 | H7: Female | I7: White | M7: Georgia
A8: 7 | B8: 2 | C8: 2 | D8: Frances | E8: Lawhon | F8: 23 | G8: 1827 | H8: Female | I8: White | M8: Alabama
A9: 8 | B9: 2 | C9: 2 | D9: William C | E9: Lawhon | F9: 21 | G9: 1829 | H9: Male | I9: White | J9: Farmhand | K9: Agriculture | M9: Tennessee
A10: 9 | B10: 2 | C10: 2 | D10: E M | E10: Lawhon | F10: 17 | G10: 1833 | H10: Female | I10: White | M10: Alabama
A11: 10 | B11: 2 | C11: 2 | D11: S | E11: Lawhon | F11: 14 | G11: 1836 | H11: Female | I11: White | M11: Alabama
A12: 11 | B12: 2 | C12: 2 | D12: D | E12: Lawhon | F12: 13 | G12: 1837 | H12: Male | I12: White | M12: Alabama
A13: 12 | B13: 2 | C13: 2 | D13: M A | E13: Lawhon | F13: 9 | G13: 1841 | H13: Female | I13: White | M13: Alabama
A14: 13 | B14: 2 | C14: 2 | D14: John W | E14: Lawhon | F14: 5 | G14: 1845 | H14: Male | I14: White | M14: Alabama
A15: 14 | B15: 2 | C15: 2 | D15: R L | E15: Lawhon | F15: 2 | G15: 1848 | H15: Female | I15: White | M15: Alabama
A16: 15 | B16: 3 | C16: 3 | D16: James W | E16: Moore | F16: 55 | G16: 1795 | H16: Male | I16: White | J16: Farmer | K16: Agriculture | L16: 4400 | M16: Georgia
A17: 16 | B17: 3 | C17: 3 | D17: M | E17: Moore | F17: 40 | G17: 1810 | H17: Female | I17: White | M17: Tennessee
A18: 17 | B18: 3 | C18: 3 | D18: H | E18: Moore | F18: 22 | G18: 1828 | H18: Male | I18: White | J18: Farmhand | K18: Agriculture | M18: Arkansas
A19: 18 | B19: 3 | C19: 3 | D19: J A | E19: Moore | F19: 20 | G19: 1830 | H19: Male | I19: White | J19: Farmhand | K19: Agriculture | M19: Arkansas
A20: 19 | B20: 3 | C20: 3 | D20: D E | E20: Moore | F20: 17 | G20: 1833 | H20: Male | I20: White | J20: Farmhand | K20: Agriculture | M20: Texas
A21: 20 | B21: 3 | C21: 3 | D21: R C | E21: Moore | F21: 16 | G21: 1834 | H21: Male | I21: White | J21: Farmhand | K21: Agriculture | M21: Texas
A22: 21 | B22: 3 | C22: 3 | D22: E | E22: Moore | F22: 14 | G22: 1836 | H22: Female | I22: White | M22: Texas | O22: Yes
A23: 22 | B23: 3 | C23: 3 | D23: B | E23: Moore | F23: 10 | G23: 1840 | H23: Male | I23: White | M23: Texas
A24: 23 | B24: 3 | C24: 3 | D24: G | E24: Moore | F24: 8 | G24: 1842 | H24: Male | I24: White | M24: Texas
A25: 24 | B25: 3 | C25: 3 | D25: N J | E25: Moore | F25: 7 | G25: 1843 | H25: Female | I25: White | M25: Texas | O25: Yes
A26: 25 | B26: 3 | C26: 3 | D26: A E | E26: Moore | F26: 5 | G26: 1845 | H26: Female | I26: White | M26: Texas
A27: 26 | B27: 3 | C27: 3 | D27: M E | E27: Moore | F27: 4 | G27: 1846 | H27: Female | I27: White | M27: Texas
A28: 27 | B28: 4 | C28: 4 | D28: Joseph | E28: Priest | F28: 32 | G28: 1818 | H28: Male | I28: White | J28: Farmer | K28: Agriculture | M28: Alabama
A29: 28 | B29: 4 | C29: 4 | D29: E | E29: Priest | F29: 28 | G29: 1822 | H29: Female | I29: White | M29: Alabama
A30: 29 | B30: 4 | C30: 4 | D30: George W | E30: Priest | F30: 10 | G30: 1840 | H30: Male | I30: White | M30: Mississippi | O30: Yes
A31: 30 | B31: 4 | C31: 4 | D31: William R | E31: Priest | F31: 8 | G31: 1842 | H31: Male | I31: White | M31: Mississippi
A32: 31 | B32: 4 | C32: 4 | D32: M C | E32: Priest | F32: 6 | G32: 1844 | H32: Female | I32: White | M32: Mississippi
A33: 32 | B33: 4 | C33: 4 | D33: L B | E33: Priest | F33: 4 | G33: 1846 | H33: Male | I33: White | M33: Mississippi
A34: 33 | B34: 4 | C34: 4 | D34: N J | E34: Priest | F34: 2 | G34: 1848 | H34: Female | I34: White | M34: Tennessee
A35: 34 | B35: 5 | C35: 5 | D35: James E | E35: Brady | F35: 40 | G35: 1810 | H35: Male | I35: White | J35: Stone Mason | K35: Construction | M35: New York
A36: 35 | B36: 5 | C36: 5 | D36: M A | E36: Brady | F36: 18 | G36: 1832 | H36: Female | I36: White | M36: Georgia
A37: 36 | B37: 5 | C37: 5 | D37: A L | E37: Brady | F37: 2 | G37: 1848 | H37: Female | I37: White | M37: Texas
A38: 37 | B38: 6 | C38: 6 | D38: Thomas | E38: Mays | F38: 47 | G38: 1803 | H38: Male | I38: White | J38: Farmer | K38: Agriculture | L38: 5000 | M38: Virginia
A39: 38 | B39: 6 | C39: 6 | D39: A | E39: Mays | F39: 32 | G39: 1818 | H39: Female | I39: White | M39: Kentucky
A40: 39 | B40: 6 | C40: 6 | D40: E F | E40: Mays | F40: 12 | G40: 1838 | H40: Female | I40: White | M40: Texas | O40: Yes
...

Sheet 1850 Not Stated Raw
A1: Line Number | B1: Dwelling Number | C1: Family Number | D1: Given Name | E1: Surname | F1: Residence Age | G1: Birth Date | H1: Gender | I1: Race | J1: Occupation | K1: Industry | L1: Real Estate | M1: Birth Place | N1: Married within the Year | O1: Attended School | P1: Cannot Read, Write | Q1: Condition | R1: Comp.
A2: 1 | B2: 1 | C2: 1 | D2: Sherman | E2: Reynolds | F2: 34 | G2: 1816 | H2: Male | I2: White | J2: Merchant | K2: Not Specified Retail Trade | L2: 10160 | M2: New York | R2: {=SUMPRODUCT(--('1850 Not Stated Clean'!A2:Q2 <> '1850 Not Stated Raw'!A2:Q2))} -> 1
A3: 2 | B3: 1 | C3: 1 | D3: Martha | E3: Reynolds | F3: 22 | G3: 1828 | H3: Female | I3: White | M3: Illinois | R3: {=SUMPRODUCT(--('1850 Not Stated Clean'!A3:Q3 <> '1850 Not Stated Raw'!A3:Q3))} -> 0
A4: 3 | B4: 1 | C4: 1 | D4: Albert B | E4: Reynolds | F4: 2 | G4: 1848 | H4: Male | I4: White | M4: Texas | R4: {=SUMPRODUCT(--('1850 Not Stated Clean'!A4:Q4 <> '1850 Not Stated Raw'!A4:Q4))} -> 0
A5: 4 | B5: 1 | C5: 1 | D5: Sherman A | E5: Reynolds | F5: 0 | G5: 1850 | H5: Male | I5: White | M5: Texas | R5: {=SUMPRODUCT(--('1850 Not Stated Clean'!A5:Q5 <> '1850 Not Stated Raw'!A5:Q5))} -> 3
A6: 5 | B6: 2 | C6: 2 | D6: H M | E6: Lawhon | F6: 45 | G6: 1805 | H6: Male | I6: White | J6: Farmer | K6: Agriculture | L6: 300 | M6: North Carolina | R6: {=SUMPRODUCT(--('1850 Not Stated Clean'!A6:Q6 <> '1850 Not Stated Raw'!A6:Q6))} -> 0
A7: 6 | B7: 2 | C7: 2 | D7: Anna | E7: Lawhon | F7: 44 | G7: 1806 | H7: Female | I7: White | M7: Georgia | R7: {=SUMPRODUCT(--('1850 Not Stated Clean'!A7:Q7 <> '1850 Not Stated Raw'!A7:Q7))} -> 0
A8: 7 | B8: 2 | C8: 2 | D8: Frances | E8: Lawhon | F8: 23 | G8: 1827 | H8: Female | I8: White | M8: Alabama | R8: {=SUMPRODUCT(--('1850 Not Stated Clean'!A8:Q8 <> '1850 Not Stated Raw'!A8:Q8))} -> 0
A9: 8 | B9: 2 | C9: 2 | D9: William C | E9: Lawhon | F9: 21 | G9: 1829 | H9: Male | I9: White | J9: Farmhand | K9: Agriculture | M9: Tennessee | R9: {=SUMPRODUCT(--('1850 Not Stated Clean'!A9:Q9 <> '1850 Not Stated Raw'!A9:Q9))} -> 0
A10: 9 | B10: 2 | C10: 2 | D10: E M | E10: Lawhon | F10: 17 | G10: 1833 | H10: Female | I10: White | M10: Alabama | R10: {=SUMPRODUCT(--('1850 Not Stated Clean'!A10:Q10 <> '1850 Not Stated Raw'!A10:Q10))} -> 0
A11: 10 | B11: 2 | C11: 2 | D11: S | E11: Lawhon | F11: 14 | G11: 1836 | H11: Female | I11: White | M11: Alabama | R11: {=SUMPRODUCT(--('1850 Not Stated Clean'!A11:Q11 <> '1850 Not Stated Raw'!A11:Q11))} -> 0
A12: 11 | B12: 2 | C12: 2 | D12: D W | E12: Lawhon | F12: 13 | G12: 1837 | H12: Male | I12: White | M12: Alabama | R12: {=SUMPRODUCT(--('1850 Not Stated Clean'!A12:Q12 <> '1850 Not Stated Raw'!A12:Q12))} -> 1
A13: 12 | B13: 2 | C13: 2 | D13: M A | E13: Lawhon | F13: 9 | G13: 1841 | H13: Female | I13: White | M13: Alabama | R13: {=SUMPRODUCT(--('1850 Not Stated Clean'!A13:Q13 <> '1850 Not Stated Raw'!A13:Q13))} -> 1
A14: 13 | B14: 2 | C14: 2 | D14: John W | E14: Lawhon | F14: 5 | G14: 1845 | H14: Male | I14: White | M14: Alabama | R14: {=SUMPRODUCT(--('1850 Not Stated Clean'!A14:Q14 <> '1850 Not Stated Raw'!A14:Q14))} -> 0
A15: 14 | B15: 2 | C15: 2 | D15: R L | E15: Lawhon | F15: 2 | G15: 1848 | H15: Female | I15: White | M15: Alabama | R15: {=SUMPRODUCT(--('1850 Not Stated Clean'!A15:Q15 <> '1850 Not Stated Raw'!A15:Q15))} -> 0
A16: 15 | B16: 3 | C16: 3 | D16: James W | E16: Moore | F16: 55 | G16: 1795 | H16: Male | I16: White | J16: Farmer | K16: Agriculture | L16: 4400 | M16: Georgia | R16: {=SUMPRODUCT(--('1850 Not Stated Clean'!A16:Q16 <> '1850 Not Stated Raw'!A16:Q16))} -> 0
A17: 16 | B17: 3 | C17: 3 | D17: M | E17: Moore | F17: 40 | G17: 1810 | H17: Female | I17: White | M17: Tennessee | R17: {=SUMPRODUCT(--('1850 Not Stated Clean'!A17:Q17 <> '1850 Not Stated Raw'!A17:Q17))} -> 0
A18: 17 | B18: 3 | C18: 3 | D18: H | E18: Moore | F18: 22 | G18: 1828 | H18: Male | I18: White | J18: Farmhand | K18: Agriculture | M18: Arkansas | R18: {=SUMPRODUCT(--('1850 Not Stated Clean'!A18:Q18 <> '1850 Not Stated Raw'!A18:Q18))} -> 0
A19: 18 | B19: 3 | C19: 3 | D19: J A | E19: Moore | F19: 20 | G19: 1830 | H19: Male | I19: White | J19: Farmhand | K19: Agriculture | M19: Arkansas | R19: {=SUMPRODUCT(--('1850 Not Stated Clean'!A19:Q19 <> '1850 Not Stated Raw'!A19:Q19))} -> 1
A20: 19 | B20: 3 | C20: 3 | D20: D E | E20: Moore | F20: 17 | G20: 1833 | H20: Male | I20: White | J20: Farmhand | K20: Agriculture | M20: Texas | R20: {=SUMPRODUCT(--('1850 Not Stated Clean'!A20:Q20 <> '1850 Not Stated Raw'!A20:Q20))} -> 0
A21: 20 | B21: 3 | C21: 3 | D21: R C | E21: Moore | F21: 16 | G21: 1834 | H21: Male | I21: White | J21: Farmhand | K21: Agriculture | M21: Texas | R21: {=SUMPRODUCT(--('1850 Not Stated Clean'!A21:Q21 <> '1850 Not Stated Raw'!A21:Q21))} -> 1
A22: 21 | B22: 3 | C22: 3 | D22: E | E22: Moore | F22: 14 | G22: 1836 | H22: Female | I22: White | M22: Texas | O22: Yes | R22: {=SUMPRODUCT(--('1850 Not Stated Clean'!A22:Q22 <> '1850 Not Stated Raw'!A22:Q22))} -> 0
A23: 22 | B23: 3 | C23: 3 | D23: B | E23: Moore | F23: 10 | G23: 1840 | H23: Male | I23: White | M23: Texas | R23: {=SUMPRODUCT(--('1850 Not Stated Clean'!A23:Q23 <> '1850 Not Stated Raw'!A23:Q23))} -> 0
A24: 23 | B24: 3 | C24: 3 | D24: G | E24: Moore | F24: 8 | G24: 1842 | H24: Male | I24: White | M24: Texas | R24: {=SUMPRODUCT(--('1850 Not Stated Clean'!A24:Q24 <> '1850 Not Stated Raw'!A24:Q24))} -> 0
A25: 24 | B25: 3 | C25: 3 | D25: N J | E25: Moore | F25: 7 | G25: 1843 | H25: Female | I25: White | M25: Texas | O25: Yes | R25: {=SUMPRODUCT(--('1850 Not Stated Clean'!A25:Q25 <> '1850 Not Stated Raw'!A25:Q25))} -> 1
A26: 25 | B26: 3 | C26: 3 | D26: A E | E26: Moore | F26: 5 | G26: 1845 | H26: Female | I26: White | M26: Texas | R26: {=SUMPRODUCT(--('1850 Not Stated Clean'!A26:Q26 <> '1850 Not Stated Raw'!A26:Q26))} -> 0
A27: 26 | B27: 3 | C27: 3 | D27: M E | E27: Moore | F27: 4 | G27: 1846 | H27: Female | I27: White | M27: Texas | R27: {=SUMPRODUCT(--('1850 Not Stated Clean'!A27:Q27 <> '1850 Not Stated Raw'!A27:Q27))} -> 1
A28: 27 | B28: 4 | C28: 4 | D28: Joseph | E28: Priest | F28: 32 | G28: 1818 | H28: Male | I28: White | J28: Farmer | K28: Agriculture | M28: Alabama | R28: {=SUMPRODUCT(--('1850 Not Stated Clean'!A28:Q28 <> '1850 Not Stated Raw'!A28:Q28))} -> 0
A29: 28 | B29: 4 | C29: 4 | D29: E | E29: Priest | F29: 28 | G29: 1822 | H29: Female | I29: White | M29: Alabama | R29: {=SUMPRODUCT(--('1850 Not Stated Clean'!A29:Q29 <> '1850 Not Stated Raw'!A29:Q29))} -> 0
A30: 29 | B30: 4 | C30: 4 | D30: George W | E30: Priest | F30: 10 | G30: 1840 | H30: Male | I30: White | M30: Mississippi | O30: Yes | R30: {=SUMPRODUCT(--('1850 Not Stated Clean'!A30:Q30 <> '1850 Not Stated Raw'!A30:Q30))} -> 0
A31: 30 | B31: 4 | C31: 4 | D31: William R | E31: Priest | F31: 8 | G31: 1842 | H31: Male | I31: White | M31: Mississippi | R31: {=SUMPRODUCT(--('1850 Not Stated Clean'!A31:Q31 <> '1850 Not Stated Raw'!A31:Q31))} -> 0
A32: 31 | B32: 4 | C32: 4 | D32: M C | E32: Priest | F32: 6 | G32: 1844 | H32: Female | I32: White | M32: Mississippi | R32: {=SUMPRODUCT(--('1850 Not Stated Clean'!A32:Q32 <> '1850 Not Stated Raw'!A32:Q32))} -> 0
A33: 32 | B33: 4 | C33: 4 | D33: L B | E33: Priest | F33: 4 | G33: 1846 | H33: Male | I33: White | M33: Mississippi | R33: {=SUMPRODUCT(--('1850 Not Stated Clean'!A33:Q33 <> '1850 Not Stated Raw'!A33:Q33))} -> 0
A34: 33 | B34: 4 | C34: 4 | D34: N J | E34: Priest | F34: 2 | G34: 1848 | H34: Female | I34: White | M34: Tennessee | R34: {=SUMPRODUCT(--('1850 Not Stated Clean'!A34:Q34 <> '1850 Not Stated Raw'!A34:Q34))} -> 1
A35: 34 | B35: 5 | C35: 5 | D35: James E | E35: Brady | F35: 40 | G35: 1810 | H35: Male | I35: White | J35: Stone Mason | K35: Construction | M35: New York | R35: {=SUMPRODUCT(--('1850 Not Stated Clean'!A35:Q35 <> '1850 Not Stated Raw'!A35:Q35))} -> 0
A36: 35 | B36: 5 | C36: 5 | D36: M A | E36: Brady | F36: 18 | G36: 1832 | H36: Female | I36: White | M36: Georgia | R36: {=SUMPRODUCT(--('1850 Not Stated Clean'!A36:Q36 <> '1850 Not Stated Raw'!A36:Q36))} -> 1
A37: 36 | B37: 5 | C37: 5 | D37: A L | E37: Brady | F37: 2 | G37: 1848 | H37: Female | I37: White | M37: Texas | R37: {=SUMPRODUCT(--('1850 Not Stated Clean'!A37:Q37 <> '1850 Not Stated Raw'!A37:Q37))} -> 0
A38: 37 | B38: 6 | C38: 6 | D38: Thomas | E38: Mays | F38: 47 | G38: 1803 | H38: Male | I38: White | J38: Farmer | K38: Agriculture | L38: 5000 | M38: Virginia | R38: {=SUMPRODUCT(--('1850 Not Stated Clean'!A38:Q38 <> '1850 Not Stated Raw'!A38:Q38))} -> 0
A39: 38 | B39: 6 | C39: 6 | D39: A | E39: Mays | F39: 32 | G39: 1818 | H39: Female | I39: White | M39: Kent | R39: {=SUMPRODUCT(--('1850 Not Stated Clean'!A39:Q39 <> '1850 Not Stated Raw'!A39:Q39))} -> 1
A40: 39 | B40: 6 | C40: 6 | D40: E F | E40: Mays | F40: 12 | G40: 1838 | H40: Female | I40: White | M40: Texas | O40: Yes | R40: {=SUMPRODUCT(--('1850 Not Stated Clean'!A40:Q40 <> '1850 Not Stated Raw'!A40:Q40))} -> 0
...

Sheet 1860 Bastrop Clean
A1: Dwelling Number | B1: Family Number | C1: Given Name | D1: Surname | E1: Age | F1: Birth Year | G1: Gender | H1: Race | I1: Occupation | J1: Real Estate Value | K1: Personal Estate Value | L1: Birth Place | M1: Married Within Year | N1: Attended School | O1: Cannot Read, Write | P1: Disability Condition
A2: 1 | B2: 1 | C2: James | D2: Nicholson | E2: 45 | F2: 1815 | G2: Male | H2: White | I2: Hotel Keeper | J2: 4000 | K2: 2000 | L2: England
A3: 1 | B3: 1 | C3: Rebecca M H | D3: Nicholson | E3: 46 | F3: 1814 | G3: Female | H3: White | J3: 1000 | L3: Tennessee
A4: 1 | B4: 1 | C4: Samuel G | D4: Nicholson | E4: 11 | F4: 1849 | G4: Male | H4: White | L4: Texas | N4: Y
A5: 1 | B5: 1 | C5: James N | D5: Nicholson | E5: 7 | F5: 1853 | G5: Male | H5: White | L5: Texas | N5: Y
A6: 1 | B6: 1 | C6: Rubell N | D6: Nicholson | E6: 5 | F6: 1855 | G6: Female | H6: White | L6: Texas
A7: 1 | B7: 1 | C7: Samuel | D7: Halker | E7: 29 | F7: 1831 | G7: Male | H7: White | I7: Drugest | K7: 2000 | L7: Georgia
A8: 1 | B8: 1 | C8: John M | D8: Webster | E8: 25 | F8: 1835 | G8: Male | H8: White | I8: Clerk | K8: 400 | L8: North Carolina
A9: 1 | B9: 1 | C9: S H | D9: Chercher | E9: 29 | F9: 1831 | G9: Male | H9: White | I9: Carpenter | L9: North Carolina
A10: 1 | B10: 1 | C10: Cornelius | D10: Philips | E10: 54 | F10: 1806 | G10: Male | H10: White | I10: Carpenter | L10: Virginia
A11: 1 | B11: 1 | C11: James B | D11: Cowan | E11: 34 | F11: 1826 | G11: Male | H11: White | I11: Brickmason | K11: 100 | L11: Virginia
A12: 1 | B12: 1 | C12: S C | D12: Wilkins | E12: 26 | F12: 1834 | G12: Male | H12: White | I12: Clerk | J12: 80 | K12: 1530 | L12: Kentucky
A13: 1 | B13: 1 | C13: John | D13: Smith | E13: 38 | F13: 1822 | G13: Male | H13: White | I13: Laborer | L13: Ireland
A14: 1 | B14: 1 | C14: John T | D14: Stanley | E14: 33 | F14: 1827 | G14: Male | H14: White | I14: Proff Searger | K14: 500 | L14: Maine
A15: 1 | B15: 1 | C15: J | D15: Rosenfield | E15: 22 | F15: 1838 | G15: Male | H15: White | I15: Clerk | K15: 9000 | L15: Texas
A16: 2 | B16: 1 | C16: H | D16: McLester | E16: 33 | F16: 1827 | G16: Male | H16: White | I16: Sawyer | K16: 400 | L16: Georgia
A17: 2 | B17: 1 | C17: S | D17: Elsworth | E17: 47 | F17: 1813 | G17: Male | H17: White | I17: Stage Driver | L17: New York
A18: 2 | B18: 1 | C18: R F | D18: Cambell | E18: 23 | F18: 1837 | G18: Male | H18: White | I18: Farmer | J18: 400 | K18: 2000 | L18: Tennessee
A19: 2 | B19: 1 | C19: H | D19: Mc Fowlard | E19: 30 | F19: 1830 | G19: Male | H19: White | I19: Stage Driver | L19: Pennsylvania
A20: 2 | B20: 1 | C20: C A | D20: Banes | E20: 32 | F20: 1828 | G20: Male | H20: White | I20: Stage Driver | L20: Tennessee
A21: 2 | B21: 1 | C21: A | D21: Hews | E21: 24 | F21: 1836 | G21: Male | H21: White | I21: Student M D | K21: 400 | L21: Ohio
A22: 3 | B22: 1 | C22: K | D22: Keslus | E22: 23 | F22: 1837 | G22: Male | H22: White | I22: Taylor | K22: 700 | L22: Saxony
A23: 3 | B23: 1 | C23: Elizabeth | D23: Barden | E23: 24 | F23: 1836 | G23: Female | H23: White | I23: Servant | L23: Texas | O23: Y
A24: 3 | B24: 1 | C24: Emma | D24: Barden | E24: 4 | F24: 1856 | G24: Female | H24: White | L24: Texas
A25: 4 | B25: 2 | C25: Charles | D25: Gnote | E25: 40 | F25: 1820 | G25: Male | H25: White | I25: Minister | K25: 4000 | L25: Germany
A26: 4 | B26: 2 | C26: Mary | D26: Gnote | E26: 40 | F26: 1820 | G26: Female | H26: White | I26: Laborer | L26: Germany
A27: 4 | B27: 2 | C27: Frits | D27: Gnote | E27: 20 | F27: 1840 | G27: Male | H27: White | L27: Germany
A28: 4 | B28: 2 | C28: Nana | D28: Gnote | E28: 5 | F28: 1855 | G28: Female | H28: White | L28: Texas
A29: 4 | B29: 2 | C29: Henry | D29: Gnote | G29: Male | H29: White | L29: Texas
A30: 5 | B30: 3 | C30: J M | D30: Hill | E30: 52 | F30: 1808 | G30: Female | H30: White | I30: Widow | J30: 500 | K30: 100 | L30: Maryland
A31: 5 | B31: 3 | C31: Thos J | D31: Hill | G31: Male | H31: White | L31: Missouri | N31: Y
A32: 6 | B32: 4 | C32: R T P | D32: Allen | E32: 46 | F32: 1814 | G32: Male | H32: White | I32: Proff Engineer | J32: 7000 | K32: 6000 | L32: Maryland
A33: 6 | B33: 4 | C33: Julia A | D33: Allen | E33: 40 | F33: 1820 | G33: Female | H33: White | L33: Tennessee
A34: 6 | B34: 4 | C34: G Howard A | D34: Allen | G34: Male | H34: White | L34: Kentucky | N34: Y
A35: 7 | B35: 5 | C35: Sam H | D35: Sims | E35: 43 | F35: 1817 | G35: Male | H35: White | I35: Master Miller | J35: 14000 | K35: 14650 | L35: Maryland
A36: 7 | B36: 5 | C36: Tulia J | D36: Sims | E36: 38 | F36: 1822 | G36: Female | H36: White | L36: Tennessee
A37: 7 | B37: 5 | C37: J W T | D37: Sims | E37: 20 | F37: 1840 | G37: Male | H37: White | I37: Clerk | L37: Texas
A38: 7 | B38: 5 | C38: J H | D38: Bruce | E38: 1 | F38: 1859 | G38: Female | H38: White | L38: Texas
A39: 7 | B39: 5 | C39: Nancy E | D39: Sims | G39: Female | H39: White | L39: Texas | N39: Y
A40: 7 | B40: 5 | C40: James O | D40: Sims | E40: 12 | F40: 1848 | G40: Male | H40: White | L40: Texas | N40: Y
...

Sheet 1860 Bastrop Raw
A1: Dwelling Number | B1: Family Number | C1: Given Name | D1: Surname | E1: Age | F1: Birth Year | G1: Gender | H1: Race | I1: Occupation | J1: Real Estate Value | K1: Personal Estate Value | L1: Birth Place | M1: Married Within Year | N1: Attended School | O1: Cannot Read, Write | P1: Disability Condition | Q1: Comp.
A2: 1 | B2: 1 | C2: Tamer | D2: Nicholson | E2: 45 | F2: 1815 | G2: Male | H2: White | I2: Hotel Keeper | J2: 4000 | K2: 2000 | L2: England | Q2: {=SUMPRODUCT(--('1860 Bastrop Clean'!A2:P2 <> '1860 Bastrop Raw'!A2:P2))} -> 1
A3: 1 | B3: 1 | C3: Rebecca M H | D3: Nicholson | E3: 46 | F3: 1814 | G3: Female | H3: White | J3: 1000 | L3: Tennessee | Q3: {=SUMPRODUCT(--('1860 Bastrop Clean'!A3:P3 <> '1860 Bastrop Raw'!A3:P3))} -> 0
A4: 1 | B4: 1 | C4: Samuel G | D4: Nicholson | E4: 11 | F4: 1849 | G4: Male | H4: White | L4: Texas | N4: Y | Q4: {=SUMPRODUCT(--('1860 Bastrop Clean'!A4:P4 <> '1860 Bastrop Raw'!A4:P4))} -> 0
A5: 1 | B5: 1 | C5: James N | D5: Nicholson | E5: 7 | F5: 1853 | G5: Male | H5: White | L5: Texas | N5: Y | Q5: {=SUMPRODUCT(--('1860 Bastrop Clean'!A5:P5 <> '1860 Bastrop Raw'!A5:P5))} -> 0
A6: 1 | B6: 1 | C6: Rubell N | D6: Nicholson | E6: 5 | F6: 1855 | G6: Female | H6: White | L6: Texas | Q6: {=SUMPRODUCT(--('1860 Bastrop Clean'!A6:P6 <> '1860 Bastrop Raw'!A6:P6))} -> 0
A7: 1 | B7: 1 | C7: Samuel | D7: Halker | E7: 29 | F7: 1831 | G7: Male | H7: White | I7: Drugest | K7: 2000 | L7: Georgia | Q7: {=SUMPRODUCT(--('1860 Bastrop Clean'!A7:P7 <> '1860 Bastrop Raw'!A7:P7))} -> 0
A8: 1 | B8: 1 | C8: John M | D8: Webster | E8: 25 | F8: 1835 | G8: Male | H8: White | I8: Clerk | K8: 400 | L8: North Carolina | Q8: {=SUMPRODUCT(--('1860 Bastrop Clean'!A8:P8 <> '1860 Bastrop Raw'!A8:P8))} -> 0
A9: 1 | B9: 1 | C9: S H | D9: Chercher | E9: 29 | F9: 1831 | G9: Male | H9: White | I9: Carpenter | L9: North Carolina | Q9: {=SUMPRODUCT(--('1860 Bastrop Clean'!A9:P9 <> '1860 Bastrop Raw'!A9:P9))} -> 0
A10: 1 | B10: 1 | C10: Cornelius | D10: Philips | E10: 54 | F10: 1806 | G10: Male | H10: White | I10: Carpenter | L10: Virginia | Q10: {=SUMPRODUCT(--('1860 Bastrop Clean'!A10:P10 <> '1860 Bastrop Raw'!A10:P10))} -> 0
A11: 1 | B11: 1 | C11: James B | D11: Cowan | E11: 34 | F11: 1826 | G11: Male | H11: White | I11: Brickmason | K11: 100 | L11: Virginia | Q11: {=SUMPRODUCT(--('1860 Bastrop Clean'!A11:P11 <> '1860 Bastrop Raw'!A11:P11))} -> 0
A12: 1 | B12: 1 | C12: S C | D12: Wilkins | E12: 26 | F12: 1834 | G12: Male | H12: White | I12: Clerk | J12: 80 | K12: 1530 | L12: Kentucky | Q12: {=SUMPRODUCT(--('1860 Bastrop Clean'!A12:P12 <> '1860 Bastrop Raw'!A12:P12))} -> 0
A13: 1 | B13: 1 | C13: John | D13: Smith | E13: 38 | F13: 1822 | G13: Male | H13: White | I13: Laborer | L13: Ireland | Q13: {=SUMPRODUCT(--('1860 Bastrop Clean'!A13:P13 <> '1860 Bastrop Raw'!A13:P13))} -> 0
A14: 1 | B14: 1 | C14: John T | D14: Stanley | E14: 33 | F14: 1827 | G14: Male | H14: White | I14: Proff Searger | K14: 500 | L14: Maine | Q14: {=SUMPRODUCT(--('1860 Bastrop Clean'!A14:P14 <> '1860 Bastrop Raw'!A14:P14))} -> 0
A15: 1 | B15: 1 | C15: J | D15: Rosenfield | E15: 22 | F15: 1838 | G15: Male | H15: White | I15: Clerk | K15: 9000 | L15: Texas | Q15: {=SUMPRODUCT(--('1860 Bastrop Clean'!A15:P15 <> '1860 Bastrop Raw'!A15:P15))} -> 0
A16: 2 | B16: 1 | C16: H | D16: McLester | E16: 33 | F16: 1827 | G16: Male | H16: White | I16: Sawyer | K16: 400 | L16: Georgia | Q16: {=SUMPRODUCT(--('1860 Bastrop Clean'!A16:P16 <> '1860 Bastrop Raw'!A16:P16))} -> 0
A17: 2 | B17: 1 | C17: S | D17: Elsworth | E17: 47 | F17: 1813 | G17: Male | H17: White | I17: Stage Driver | L17: New York | Q17: {=SUMPRODUCT(--('1860 Bastrop Clean'!A17:P17 <> '1860 Bastrop Raw'!A17:P17))} -> 0
A18: 2 | B18: 1 | C18: R F | D18: Cambell | E18: 23 | F18: 1837 | G18: Male | H18: White | I18: Farmer | J18: 400 | K18: 2000 | L18: Tennessee | Q18: {=SUMPRODUCT(--('1860 Bastrop Clean'!A18:P18 <> '1860 Bastrop Raw'!A18:P18))} -> 0
A19: 2 | B19: 1 | C19: H | D19: Mc Fowlard | E19: 30 | F19: 1830 | G19: Male | H19: White | I19: Stage Driver | L19: Pennsylvania | Q19: {=SUMPRODUCT(--('1860 Bastrop Clean'!A19:P19 <> '1860 Bastrop Raw'!A19:P19))} -> 0
A20: 2 | B20: 1 | C20: C A | D20: Banes | E20: 32 | F20: 1828 | G20: Male | H20: White | I20: Stage Driver | L20: Tennessee | Q20: {=SUMPRODUCT(--('1860 Bastrop Clean'!A20:P20 <> '1860 Bastrop Raw'!A20:P20))} -> 0
A21: 2 | B21: 1 | C21: A | D21: Hews | E21: 24 | F21: 1836 | G21: Male | H21: White | I21: Student M D | K21: 400 | L21: Ohio | Q21: {=SUMPRODUCT(--('1860 Bastrop Clean'!A21:P21 <> '1860 Bastrop Raw'!A21:P21))} -> 0
A22: 3 | B22: 1 | C22: K | D22: Keslus | E22: 23 | F22: 1837 | G22: Male | H22: White | I22: Taylor | K22: 700 | L22: Saxony | Q22: {=SUMPRODUCT(--('1860 Bastrop Clean'!A22:P22 <> '1860 Bastrop Raw'!A22:P22))} -> 0
A23: 3 | B23: 1 | C23: Elizabeth | D23: Barden | E23: 24 | F23: 1836 | G23: Female | H23: White | I23: Servant | L23: Texas | O23: Y | Q23: {=SUMPRODUCT(--('1860 Bastrop Clean'!A23:P23 <> '1860 Bastrop Raw'!A23:P23))} -> 0
A24: 3 | B24: 1 | C24: Emma | D24: Barden | E24: 4 | F24: 1856 | G24: Female | H24: White | L24: Texas | Q24: {=SUMPRODUCT(--('1860 Bastrop Clean'!A24:P24 <> '1860 Bastrop Raw'!A24:P24))} -> 0
A25: 4 | B25: 2 | C25: Charles | D25: Gnote | E25: 40 | F25: 1820 | G25: Male | H25: White | I25: Minister | K25: 4000 | L25: Germany | Q25: {=SUMPRODUCT(--('1860 Bastrop Clean'!A25:P25 <> '1860 Bastrop Raw'!A25:P25))} -> 0
A26: 4 | B26: 2 | C26: Mary | D26: Gnote | E26: 40 | F26: 1820 | G26: Female | H26: White | I26: Laborer | L26: Germany | Q26: {=SUMPRODUCT(--('1860 Bastrop Clean'!A26:P26 <> '1860 Bastrop Raw'!A26:P26))} -> 0
A27: 4 | B27: 2 | C27: Frits | D27: Gnote | E27: 20 | F27: 1840 | G27: Male | H27: White | L27: Germany | Q27: {=SUMPRODUCT(--('1860 Bastrop Clean'!A27:P27 <> '1860 Bastrop Raw'!A27:P27))} -> 0
A28: 4 | B28: 2 | C28: Nana | D28: Gnote | E28: 5 | F28: 1855 | G28: Female | H28: White | L28: Texas | Q28: {=SUMPRODUCT(--('1860 Bastrop Clean'!A28:P28 <> '1860 Bastrop Raw'!A28:P28))} -> 0
A29: 4 | B29: 2 | C29: Henry | D29: Gnote | G29: Male | H29: White | L29: Texas | Q29: {=SUMPRODUCT(--('1860 Bastrop Clean'!A29:P29 <> '1860 Bastrop Raw'!A29:P29))} -> 0
A30: 5 | B30: 3 | C30: J M | D30: Hill | E30: 52 | F30: 1808 | G30: Female | H30: White | I30: Widow | J30: 500 | K30: 100 | L30: Maryland | Q30: {=SUMPRODUCT(--('1860 Bastrop Clean'!A30:P30 <> '1860 Bastrop Raw'!A30:P30))} -> 0
A31: 5 | B31: 3 | C31: Thos J | D31: Hill | G31: Male | H31: White | L31: Missouri | N31: Y | Q31: {=SUMPRODUCT(--('1860 Bastrop Clean'!A31:P31 <> '1860 Bastrop Raw'!A31:P31))} -> 0
A32: 6 | B32: 4 | C32: R T P | D32: Allen | E32: 46 | F32: 1814 | G32: Male | H32: White | I32: Proff Engineer | J32: 7000 | K32: 6000 | L32: Maryland | Q32: {=SUMPRODUCT(--('1860 Bastrop Clean'!A32:P32 <> '1860 Bastrop Raw'!A32:P32))} -> 0
A33: 6 | B33: 4 | C33: Julia A | D33: Allen | E33: 40 | F33: 1820 | G33: Female | H33: White | L33: Tennessee | Q33: {=SUMPRODUCT(--('1860 Bastrop Clean'!A33:P33 <> '1860 Bastrop Raw'!A33:P33))} -> 0
A34: 6 | B34: 4 | C34: G Howard A | D34: Allen | G34: Male | H34: White | L34: Kentucky | N34: Y | Q34: {=SUMPRODUCT(--('1860 Bastrop Clean'!A34:P34 <> '1860 Bastrop Raw'!A34:P34))} -> 0
A35: 7 | B35: 5 | C35: Sam H | D35: Sims | E35: 43 | F35: 1817 | G35: Male | H35: White | I35: Master Miller | J35: 14000 | K35: 14650 | L35: Maryland | Q35: {=SUMPRODUCT(--('1860 Bastrop Clean'!A35:P35 <> '1860 Bastrop Raw'!A35:P35))} -> 0
A36: 7 | B36: 5 | C36: Tulia J | D36: Sims | E36: 38 | F36: 1822 | G36: Female | H36: White | L36: Tennessee | Q36: {=SUMPRODUCT(--('1860 Bastrop Clean'!A36:P36 <> '1860 Bastrop Raw'!A36:P36))} -> 0
A37: 7 | B37: 5 | C37: J W T | D37: Sims | E37: 20 | F37: 1840 | G37: Male | H37: White | I37: Clerk | L37: Texas | Q37: {=SUMPRODUCT(--('1860 Bastrop Clean'!A37:P37 <> '1860 Bastrop Raw'!A37:P37))} -> 0
A38: 7 | B38: 5 | C38: J H | D38: Bruce | E38: 1 | F38: 1859 | G38: Female | H38: White | L38: Texas | Q38: {=SUMPRODUCT(--('1860 Bastrop Clean'!A38:P38 <> '1860 Bastrop Raw'!A38:P38))} -> 0
A39: 7 | B39: 5 | C39: Nancy E | D39: Sims | G39: Female | H39: White | L39: Texas | N39: Y | Q39: {=SUMPRODUCT(--('1860 Bastrop Clean'!A39:P39 <> '1860 Bastrop Raw'!A39:P39))} -> 0
A40: 7 | B40: 5 | C40: James O | D40: Sims | E40: 12 | F40: 1848 | G40: Male | H40: White | L40: Texas | N40: Y | Q40: {=SUMPRODUCT(--('1860 Bastrop Clean'!A40:P40 <> '1860 Bastrop Raw'!A40:P40))} -> 0
...

Sheet 1870 Bastrop Clean
A1: Line Number | B1: Dwelling Number | C1: Family Number | D1: Surname | E1: Given Name | F1: Age | G1: Birth Year | H1: Gender | I1: Race | J1: Occupation | K1: Real Estate Value | L1: Personal Estate Value | M1: Birthplace | N1: Father of Foreign Birth | O1: Mother of Foreign Birth | P1: Birth Month | Q1: Marriage Month | R1: Attended School | S1: Cannot Read | T1: Cannot Write | U1: Condition | V1: Male Citizen Over 21 | W1: Denied Voting Rights
A2: 1 | B2: 1 | C2: 1 | D2: Schaefer | E2: Cho | F2: 54 | G2: 1816 | H2: Male | I2: White | J2: Farmer | K2: 1000 | L2: 300 | M2: Bavaria / Bayern | N2: Yes | O2: Yes | V2: Yes
A3: =A2+1 -> 2 | B3: 1 | C3: 1 | D3: Schaefer | E3: Barbara | F3: 54 | G3: 1816 | H3: Female | I3: White | J3: Keeping House | M3: Bavaria / Bayern | N3: Yes | O3: Yes
A4: =A3+1 -> 3 | B4: 1 | C4: 1 | D4: Schaefer | E4: Andreas | F4: 24 | G4: 1846 | H4: Male | I4: White | J4: Farm Laborer | M4: Texas | N4: Yes | O4: Yes | V4: Yes
A5: =A4+1 -> 4 | B5: 1 | C5: 2 | D5: Geis | E5: Christian | F5: 26 | G5: 1844 | H5: Male | I5: White | J5: Farmer | K5: 600 | L5: 200 | M5: Nassau | N5: Yes | O5: Yes | V5: Yes
A6: =A5+1 -> 5 | B6: 1 | C6: 2 | D6: Geis | E6: Barbara | F6: 27 | G6: 1843 | H6: Female | I6: White | J6: Keeping House | M6: Bavaria / Bayern | N6: Yes | O6: Yes
A7: =A6+1 -> 6 | B7: 1 | C7: 2 | D7: Geis | E7: Helene | F7: 7 | G7: 1863 | H7: Female | I7: White | M7: Texas | N7: Yes | O7: Yes
A8: =A7+1 -> 7 | B8: 1 | C8: 2 | D8: Geis | E8: Henry | F8: 2 | G8: 1868 | H8: Male | I8: White | M8: Texas | N8: Yes | O8: Yes
A9: =A8+1 -> 8 | B9: 2 | C9: 3 | D9: Schefsky | E9: C R V | F9: 40 | G9: 1830 | H9: Male | I9: White | J9: Teacher & DU Sea | K9: 1000 | L9: 400 | M9: Hannover / Hanover | N9: Yes | O9: Yes | V9: Yes
A10: =A9+1 -> 9 | B10: 2 | C10: 3 | D10: Schefsky | E10: Johanna | F10: 51 | G10: 1819 | H10: Female | I10: White | J10: Keeping House | M10: Holstein | N10: Yes | O10: Yes
A11: =A10+1 -> 10 | B11: 3 | C11: 4 | D11: Wertsner | E11: Chas | F11: 40 | G11: 1830 | H11: Male | I11: White | J11: Merchant & Post M | K11: 1500 | L11: 2000 | M11: Saxonia | N11: Yes | O11: Yes | V11: Yes
A12: =A11+1 -> 11 | B12: 3 | C12: 4 | D12: Wertsner | E12: Franziska | F12: 31 | G12: 1839 | H12: Female | I12: White | J12: Keeping House | M12: Bohemia | N12: Yes | O12: Yes
A13: =A12+1 -> 12 | B13: 3 | C13: 4 | D13: Wertsner | E13: Oskar | F13: 11 | G13: 1859 | H13: Male | I13: White | J13: Farmer | M13: Texas | N13: Yes | O13: Yes | R13: Yes
A14: =A13+1 -> 13 | B14: 3 | C14: 4 | D14: Wertsner | E14: Selma | F14: 7 | G14: 1863 | H14: Female | I14: White | M14: Texas | N14: Yes | O14: Yes
A15: =A14+1 -> 14 | B15: 3 | C15: 4 | D15: Wertsner | E15: Pauline | F15: 5 | G15: 1865 | H15: Female | I15: White | M15: Texas | N15: Yes | O15: Yes
A16: =A15+1 -> 15 | B16: 3 | C16: 4 | D16: Wertsner | E16: Elisabeth | F16: 1 | G16: 1869 | H16: Female | I16: White | M16: Texas | N16: Yes | O16: Yes
A17: =A16+1 -> 16 | B17: 3 | C17: 4a | D17: Hanke | E17: Anna | F17: 19 | G17: 1851 | H17: Female | I17: White | J17: Domestic Servant | M17: Prussia | N17: Yes | O17: Yes
A18: =A17+1 -> 17 | B18: 3 | C18: 4b | D18: Hopler | E18: John | F18: 53 | G18: 1817 | H18: Male | I18: White | J18: Domestic Servant | M18: Mecklenburg | N18: Yes | O18: Yes | V18: Yes
A19: =A18+1 -> 18 | B19: 3 | C19: 4c | D19: Woehl | E19: Joseph | F19: 16 | G19: 1854 | H19: Male | I19: White | J19: Clerk In Store | M19: Texas | N19: Yes | O19: Yes
A20: =A19+1 -> 19 | B20: 4 | C20: 5 | D20: Glockner | E20: Moritz | F20: 57 | G20: 1813 | H20: Male | I20: White | J20: Baker & Mercha | K20: 2000 | L20: 1000 | M20: Bohemia | N20: Yes | O20: Yes | V20: Yes
A21: =A20+1 -> 20 | B21: 4 | C21: 5 | D21: Glockner | E21: Solovia | F21: 34 | G21: 1836 | H21: Female | I21: White | J21: Keeping House | M21: Bohemia | N21: Yes | O21: Yes
A22: =A21+1 -> 21 | B22: 4 | C22: 5 | D22: Glockner | E22: Salonia | F22: 13 | G22: 1857 | H22: Female | I22: White | M22: Texas | N22: Yes | O22: Yes | R22: Yes
A23: =A22+1 -> 22 | B23: 4 | C23: 5 | D23: Glockner | E23: Joseph | F23: 10 | G23: 1860 | H23: Male | I23: White | M23: Texas | N23: Yes | O23: Yes | R23: Yes
A24: =A23+1 -> 23 | B24: 4 | C24: 5 | D24: Glockner | E24: Tracy | F24: 8 | G24: 1862 | H24: Male | I24: White | M24: Texas | N24: Yes | O24: Yes | R24: Yes
A25: =A24+1 -> 24 | B25: 4 | C25: 5 | D25: Glockner | E25: Anton | F25: 1 | G25: 1869 | H25: Male | I25: White | M25: Texas | N25: Yes | O25: Yes
A26: =A25+1 -> 25 | B26: 4 | C26: 5 | D26: Glockner | E26: William | F26: 45820 | G26: 1870 | H26: Male | I26: White | M26: Texas | N26: Yes | O26: Yes | P26: Feb
A27: =A26+1 -> 26 | B27: 5 | C27: 6 | D27: Spifer | E27: George | F27: 24 | G27: 1846 | H27: Male | I27: White | J27: Sadler & Harness | K27: 500 | M27: Hesse-Darmstadt / Hessen-Darmstadt | N27: Yes | O27: Yes | V27: Yes
A28: =A27+1 -> 27 | B28: 5 | C28: 6 | D28: Spifer | E28: Antonia | F28: 20 | G28: 1850 | H28: Female | I28: White | J28: Keeping House | M28: Bohemia | N28: Yes | O28: Yes
A29: =A28+1 -> 28 | B29: 5 | C29: 6a | D29: Stelzig | E29: Anton | F29: 20 | G29: 1850 | H29: Male | I29: White | J29: Apprent To Saw | M29: Bohemia | N29: Yes | O29: Yes
A30: =A29+1 -> 29 | B30: 6 | C30: 7 | D30: Coppel | E30: Henry | F30: 30 | G30: 1840 | H30: Male | I30: White | J30: Merchant In Retail | K30: 600 | L30: 2000 | M30: Hesse-Darmstadt / Hessen-Darmstadt | N30: Yes | O30: Yes | V30: Yes
A31: =A30+1 -> 30 | B31: 6 | C31: 7 | D31: Coppel | E31: Caroline | F31: 24 | G31: 1846 | H31: Female | I31: White | J31: Keeping House | M31: Hesse-Darmstadt / Hessen-Darmstadt | N31: Yes | O31: Yes
A32: =A31+1 -> 31 | B32: 6 | C32: 7 | D32: Coppel | E32: Jacob | F32: 26 | G32: 1844 | H32: Male | I32: White | J32: Merchant In Retail | M32: Hesse-Darmstadt / Hessen-Darmstadt | N32: Yes | O32: Yes | V32: Yes
A33: =A32+1 -> 32 | B33: 7 | C33: 8 | D33: Spittler | E33: N M | F33: 37 | G33: 1833 | H33: Male | I33: White | J33: Farmer & Dik Co | K33: 1500 | L33: 500 | M33: Indiana | N33: Yes | V33: Yes
A34: =A33+1 -> 33 | B34: 7 | C34: 8 | D34: Spittler | E34: Sarah | F34: 33 | G34: 1837 | H34: Female | I34: White | J34: Keeping House | M34: Texas
A35: =A34+1 -> 34 | B35: 7 | C35: 8 | D35: Spittler | E35: Jos M | F35: 11 | G35: 1859 | H35: Male | I35: White | M35: Texas | R35: Yes
A36: =A35+1 -> 35 | B36: 7 | C36: 8 | D36: Spittler | E36: Florence | F36: 9 | G36: 1861 | H36: Female | I36: White | M36: Texas | R36: Yes
A37: =A36+1 -> 36 | B37: 7 | C37: 8 | D37: Spittler | E37: Allen | F37: 6 | G37: 1864 | H37: Male | I37: White | M37: Texas
A38: =A37+1 -> 37 | B38: 7 | C38: 8 | D38: Spittler | E38: W M | F38: 2 | G38: 1868 | H38: Male | I38: White | M38: Texas
A39: =A38+1 -> 38 | B39: 7 | C39: 8a | D39: Sneed | E39: Cyntah | F39: 35 | G39: 1835 | H39: Female | I39: Black | J39: Domestic Servant | M39: Georgia | S39: Yes | T39: Yes | U39: B-.
A40: =A39+1 -> 39 | B40: 7 | C40: 8b | D40: Wilkins | E40: Haney | F40: 53 | G40: 1817 | H40: Female | I40: Black | J40: Farm Laborer | M40: Alabama | S40: Yes | T40: Yes | U40: B-.
...

Sheet 1870 Bastrop Raw
A1: Line Number | B1: Dwelling Number | C1: Family Number | D1: Surname | E1: Given Name | F1: Age | G1: Birth Year | H1: Gender | I1: Race | J1: Occupation | K1: Real Estate Value | L1: Personal Estate Value | M1: Birthplace | N1: Father of Foreign Birth | O1: Mother of Foreign Birth | P1: Birth Month | Q1: Marriage Month | R1: Attended School | S1: Cannot Read | T1: Cannot Write | U1: Condition | V1: Male Citizen Over 21 | W1: Denied Voting Rights
A2: 8 | B2: 2 | C2: 3 | D2: Schefsky | E2: C R V | F2: 40 | G2: 1830 | H2: Male | I2: White | J2: Teacher & DU Sea | K2: 1000 | L2: 400 | M2: Hannover / Hanover | N2: Yes | O2: Yes | V2: Yes | X2: {=SUMPRODUCT(--(INDEX('1870 Bastrop Clean'!A:W, MATCH(A2 & "|" & B2,'1870 Bastrop Clean'!A:A & "|" & '1870 Bastrop Clean'!B:B, 0), 0) <> '1870 Bastrop Raw'!A2:W2))} -> 0
A3: 9 | B3: 2 | C3: 3 | D3: Schefsky | E3: Johanna | F3: 51 | G3: 1819 | H3: Female | I3: White | J3: Keeping House | M3: Holstein | N3: Yes | O3: Yes | X3: {=SUMPRODUCT(--(INDEX('1870 Bastrop Clean'!A:W, MATCH(A3 & "|" & B3,'1870 Bastrop Clean'!A:A & "|" & '1870 Bastrop Clean'!B:B, 0), 0) <> '1870 Bastrop Raw'!A3:W3))} -> 0
A4: 29 | B4: 6 | C4: 7 | D4: Coppel | E4: Henry | F4: 30 | G4: 1840 | H4: Male | I4: White | J4: Merchant In Retail | K4: 600 | L4: 2000 | M4: Hesse-Darmstadt / Hessen-Darmstadt | N4: Yes | O4: Yes | V4: Yes | X4: {=SUMPRODUCT(--(INDEX('1870 Bastrop Clean'!A:W, MATCH(A4 & "|" & B4,'1870 Bastrop Clean'!A:A & "|" & '1870 Bastrop Clean'!B:B, 0), 0) <> '1870 Bastrop Raw'!A4:W4))} -> 0
A5: 30 | B5: 6 | C5: 7 | D5: Coppel | E5: Caroline | F5: 24 | G5: 1846 | H5: Female | I5: White | J5: Keeping House | M5: Hesse-Darmstadt / Hessen-Darmstadt | N5: Yes | O5: Yes | X5: {=SUMPRODUCT(--(INDEX('1870 Bastrop Clean'!A:W, MATCH(A5 & "|" & B5,'1870 Bastrop Clean'!A:A & "|" & '1870 Bastrop Clean'!B:B, 0), 0) <> '1870 Bastrop Raw'!A5:W5))} -> 0
A6: 31 | B6: 6 | C6: 7 | D6: Coppel | E6: Jacob | F6: 26 | G6: 1844 | H6: Male | I6: White | J6: Merchant In Retail | M6: Hesse-Darmstadt / Hessen-Darmstadt | N6: Yes | O6: Yes | V6: Yes | X6: {=SUMPRODUCT(--(INDEX('1870 Bastrop Clean'!A:W, MATCH(A6 & "|" & B6,'1870 Bastrop Clean'!A:A & "|" & '1870 Bastrop Clean'!B:B, 0), 0) <> '1870 Bastrop Raw'!A6:W6))} -> 0
A7: 1 | B7: 1 | C7: 1 | D7: Schaefer | E7: Cho | F7: 54 | G7: 1816 | H7: Male | I7: White | J7: Farmer | K7: 1000 | L7: 300 | M7: Bavaria / Bayern | N7: Yes | O7: Yes | V7: Yes | X7: {=SUMPRODUCT(--(INDEX('1870 Bastrop Clean'!A:W, MATCH(A7 & "|" & B7,'1870 Bastrop Clean'!A:A & "|" & '1870 Bastrop Clean'!B:B, 0), 0) <> '1870 Bastrop Raw'!A7:W7))} -> 0
A8: 2 | B8: 1 | C8: 1 | D8: Schaefer | E8: Barbara | F8: 54 | G8: 1816 | H8: Female | I8: White | J8: Keeping House | M8: Bavaria / Bayern | N8: Yes | O8: Yes | X8: {=SUMPRODUCT(--(INDEX('1870 Bastrop Clean'!A:W, MATCH(A8 & "|" & B8,'1870 Bastrop Clean'!A:A & "|" & '1870 Bastrop Clean'!B:B, 0), 0) <> '1870 Bastrop Raw'!A8:W8))} -> 0
A9: 3 | B9: 1 | C9: 1 | D9: Schaefer | E9: Andreas | F9: 24 | G9: 1846 | H9: Male | I9: White | J9: Farm Laborer | M9: Texas | N9: Yes | O9: Yes | V9: Yes | X9: {=SUMPRODUCT(--(INDEX('1870 Bastrop Clean'!A:W, MATCH(A9 & "|" & B9,'1870 Bastrop Clean'!A:A & "|" & '1870 Bastrop Clean'!B:B, 0), 0) <> '1870 Bastrop Raw'!A9:W9))} -> 0
A10: 4 | B10: 1 | C10: 2 | D10: Geis | E10: Christian | F10: 26 | G10: 1844 | H10: Male | I10: White | J10: Farmer | K10: 600 | L10: 200 | M10: Nassau | N10: Yes | O10: Yes | V10: Yes | X10: {=SUMPRODUCT(--(INDEX('1870 Bastrop Clean'!A:W, MATCH(A10 & "|" & B10,'1870 Bastrop Clean'!A:A & "|" & '1870 Bastrop Clean'!B:B, 0), 0) <> '1870 Bastrop Raw'!A10:W10))} -> 0
A11: 5 | B11: 1 | C11: 2 | D11: Geis | E11: Barbara | F11: 27 | G11: 1843 | H11: Female | I11: White | J11: Keeping House | M11: Bavaria / Bayern | N11: Yes | O11: Yes | X11: {=SUMPRODUCT(--(INDEX('1870 Bastrop Clean'!A:W, MATCH(A11 & "|" & B11,'1870 Bastrop Clean'!A:A & "|" & '1870 Bastrop Clean'!B:B, 0), 0) <> '1870 Bastrop Raw'!A11:W11))} -> 0
A12: 6 | B12: 1 | C12: 2 | D12: Geis | E12: Helene | F12: 7 | G12: 1863 | H12: Female | I12: White | M12: Texas | N12: Yes | O12: Yes | X12: {=SUMPRODUCT(--(INDEX('1870 Bastrop Clean'!A:W, MATCH(A12 & "|" & B12,'1870 Bastrop Clean'!A:A & "|" & '1870 Bastrop Clean'!B:B, 0), 0) <> '1870 Bastrop Raw'!A12:W12))} -> 0
A13: 7 | B13: 1 | C13: 2 | D13: Geis | E13: Henry | F13: 2 | G13: 1868 | H13: Male | I13: White | M13: Texas | N13: Yes | O13: Yes | X13: {=SUMPRODUCT(--(INDEX('1870 Bastrop Clean'!A:W, MATCH(A13 & "|" & B13,'1870 Bastrop Clean'!A:A & "|" & '1870 Bastrop Clean'!B:B, 0), 0) <> '1870 Bastrop Raw'!A13:W13))} -> 0
A14: 10 | B14: 3 | C14: 4 | D14: Wertsner | E14: Chas | F14: 40 | G14: 1830 | H14: Male | I14: White | J14: Merchant & Post M | K14: 1500 | L14: 2000 | M14: Saxonia | N14: Yes | O14: Yes | V14: Yes | X14: {=SUMPRODUCT(--(INDEX('1870 Bastrop Clean'!A:W, MATCH(A14 & "|" & B14,'1870 Bastrop Clean'!A:A & "|" & '1870 Bastrop Clean'!B:B, 0), 0) <> '1870 Bastrop Raw'!A14:W14))} -> 0
A15: 11 | B15: 3 | C15: 4 | D15: Wertsner | E15: Franziska | F15: 31 | G15: 1839 | H15: Female | I15: White | J15: Keeping House | M15: Bohemia | N15: Yes | O15: Yes | X15: {=SUMPRODUCT(--(INDEX('1870 Bastrop Clean'!A:W, MATCH(A15 & "|" & B15,'1870 Bastrop Clean'!A:A & "|" & '1870 Bastrop Clean'!B:B, 0), 0) <> '1870 Bastrop Raw'!A15:W15))} -> 0
A16: 12 | B16: 3 | C16: 4 | D16: Wertsner | E16: Oskar | F16: 11 | G16: 1859 | H16: Male | I16: White | J16: Farmer | M16: Texas | N16: Yes | O16: Yes | R16: Yes | X16: {=SUMPRODUCT(--(INDEX('1870 Bastrop Clean'!A:W, MATCH(A16 & "|" & B16,'1870 Bastrop Clean'!A:A & "|" & '1870 Bastrop Clean'!B:B, 0), 0) <> '1870 Bastrop Raw'!A16:W16))} -> 0
A17: 13 | B17: 3 | C17: 4 | D17: Wertsner | E17: Selma | F17: 7 | G17: 1863 | H17: Female | I17: White | M17: Texas | N17: Yes | O17: Yes | X17: {=SUMPRODUCT(--(INDEX('1870 Bastrop Clean'!A:W, MATCH(A17 & "|" & B17,'1870 Bastrop Clean'!A:A & "|" & '1870 Bastrop Clean'!B:B, 0), 0) <> '1870 Bastrop Raw'!A17:W17))} -> 0
A18: 14 | B18: 3 | C18: 4 | D18: Wertsner | E18: Pauline | F18: 5 | G18: 1865 | H18: Female | I18: White | M18: Texas | N18: Yes | O18: Yes | X18: {=SUMPRODUCT(--(INDEX('1870 Bastrop Clean'!A:W, MATCH(A18 & "|" & B18,'1870 Bastrop Clean'!A:A & "|" & '1870 Bastrop Clean'!B:B, 0), 0) <> '1870 Bastrop Raw'!A18:W18))} -> 0
A19: 15 | B19: 3 | C19: 4 | D19: Wertsner | E19: Elisabeth | H19: Female | I19: White | M19: Texas | N19: Yes | O19: Yes | X19: {=SUMPRODUCT(--(INDEX('1870 Bastrop Clean'!A:W, MATCH(A19 & "|" & B19,'1870 Bastrop Clean'!A:A & "|" & '1870 Bastrop Clean'!B:B, 0), 0) <> '1870 Bastrop Raw'!A19:W19))} -> 2
A20: 16 | B20: 3 | C20: 4 | D20: Hanke | E20: Anna | F20: 19 | G20: 1851 | H20: Female | I20: White | J20: Domestic Servant | M20: Prussia | N20: Yes | O20: Yes | X20: {=SUMPRODUCT(--(INDEX('1870 Bastrop Clean'!A:W, MATCH(A20 & "|" & B20,'1870 Bastrop Clean'!A:A & "|" & '1870 Bastrop Clean'!B:B, 0), 0) <> '1870 Bastrop Raw'!A20:W20))} -> 1
A21: 17 | B21: 3 | C21: 4 | D21: Hopler | E21: John | F21: 53 | G21: 1817 | H21: Male | I21: White | J21: Domestic Servant | M21: Mecklenburg | N21: Yes | O21: Yes | V21: Yes | X21: {=SUMPRODUCT(--(INDEX('1870 Bastrop Clean'!A:W, MATCH(A21 & "|" & B21,'1870 Bastrop Clean'!A:A & "|" & '1870 Bastrop Clean'!B:B, 0), 0) <> '1870 Bastrop Raw'!A21:W21))} -> 1
A22: 18 | B22: 3 | C22: 4 | D22: Woehl | E22: Joseph | F22: 16 | G22: 1854 | H22: Male | I22: White | J22: Clerk In Store | M22: Texas | N22: Yes | O22: Yes | X22: {=SUMPRODUCT(--(INDEX('1870 Bastrop Clean'!A:W, MATCH(A22 & "|" & B22,'1870 Bastrop Clean'!A:A & "|" & '1870 Bastrop Clean'!B:B, 0), 0) <> '1870 Bastrop Raw'!A22:W22))} -> 1
A23: 19 | B23: 4 | C23: 5 | D23: Glockner | E23: Moritz | F23: 57 | G23: 1813 | H23: Male | I23: White | J23: Baker & Mercha | K23: 2000 | L23: 1000 | M23: Bohemia | N23: Yes | O23: Yes | V23: Yes | X23: {=SUMPRODUCT(--(INDEX('1870 Bastrop Clean'!A:W, MATCH(A23 & "|" & B23,'1870 Bastrop Clean'!A:A & "|" & '1870 Bastrop Clean'!B:B, 0), 0) <> '1870 Bastrop Raw'!A23:W23))} -> 0
A24: 20 | B24: 4 | C24: 5 | D24: Glockner | E24: Solovia | F24: 34 | G24: 1836 | H24: Female | I24: White | J24: Keeping House | M24: Bohemia | N24: Yes | O24: Yes | X24: {=SUMPRODUCT(--(INDEX('1870 Bastrop Clean'!A:W, MATCH(A24 & "|" & B24,'1870 Bastrop Clean'!A:A & "|" & '1870 Bastrop Clean'!B:B, 0), 0) <> '1870 Bastrop Raw'!A24:W24))} -> 0
A25: 21 | B25: 4 | C25: 5 | D25: Glockner | E25: Salonia | F25: 13 | G25: 1857 | H25: Female | I25: White | M25: Texas | N25: Yes | O25: Yes | R25: Yes | X25: {=SUMPRODUCT(--(INDEX('1870 Bastrop Clean'!A:W, MATCH(A25 & "|" & B25,'1870 Bastrop Clean'!A:A & "|" & '1870 Bastrop Clean'!B:B, 0), 0) <> '1870 Bastrop Raw'!A25:W25))} -> 0
A26: 22 | B26: 4 | C26: 5 | D26: Glockner | E26: Joseph | F26: 10 | G26: 1860 | H26: Male | I26: White | M26: Texas | N26: Yes | O26: Yes | R26: Yes | X26: {=SUMPRODUCT(--(INDEX('1870 Bastrop Clean'!A:W, MATCH(A26 & "|" & B26,'1870 Bastrop Clean'!A:A & "|" & '1870 Bastrop Clean'!B:B, 0), 0) <> '1870 Bastrop Raw'!A26:W26))} -> 0
A27: 23 | B27: 4 | C27: 5 | D27: Glockner | E27: Tracy | F27: 8 | G27: 1862 | H27: Male | I27: White | M27: Texas | N27: Yes | O27: Yes | R27: Yes | X27: {=SUMPRODUCT(--(INDEX('1870 Bastrop Clean'!A:W, MATCH(A27 & "|" & B27,'1870 Bastrop Clean'!A:A & "|" & '1870 Bastrop Clean'!B:B, 0), 0) <> '1870 Bastrop Raw'!A27:W27))} -> 0
A28: 24 | B28: 4 | C28: 5 | D28: Glockner | E28: Anton | H28: Male | I28: White | M28: Texas | N28: Yes | O28: Yes | X28: {=SUMPRODUCT(--(INDEX('1870 Bastrop Clean'!A:W, MATCH(A28 & "|" & B28,'1870 Bastrop Clean'!A:A & "|" & '1870 Bastrop Clean'!B:B, 0), 0) <> '1870 Bastrop Raw'!A28:W28))} -> 2
A29: 25 | B29: 4 | C29: 5 | D29: Glockner | E29: William | F29: 45820 | H29: Male | I29: White | M29: Texas | N29: Yes | O29: Yes | P29: Feb | X29: {=SUMPRODUCT(--(INDEX('1870 Bastrop Clean'!A:W, MATCH(A29 & "|" & B29,'1870 Bastrop Clean'!A:A & "|" & '1870 Bastrop Clean'!B:B, 0), 0) <> '1870 Bastrop Raw'!A29:W29))} -> 1
A30: 26 | B30: 5 | C30: 6 | D30: Spifer | E30: George | F30: 24 | G30: 1846 | H30: Male | I30: White | J30: Sadler & Harness | K30: 500 | M30: Hesse-Darmstadt / Hessen-Darmstadt | N30: Yes | O30: Yes | V30: Yes | X30: {=SUMPRODUCT(--(INDEX('1870 Bastrop Clean'!A:W, MATCH(A30 & "|" & B30,'1870 Bastrop Clean'!A:A & "|" & '1870 Bastrop Clean'!B:B, 0), 0) <> '1870 Bastrop Raw'!A30:W30))} -> 0
A31: 27 | B31: 5 | C31: 6 | D31: Spifer | E31: Antonia | H31: Female | I31: White | J31: Keeping House | M31: Bohemia | N31: Yes | O31: Yes | X31: {=SUMPRODUCT(--(INDEX('1870 Bastrop Clean'!A:W, MATCH(A31 & "|" & B31,'1870 Bastrop Clean'!A:A & "|" & '1870 Bastrop Clean'!B:B, 0), 0) <> '1870 Bastrop Raw'!A31:W31))} -> 2
A32: 28 | B32: 5 | C32: 6 | D32: Stelzig | E32: Anton | H32: Male | I32: White | J32: Apprent To Saw | M32: Bohemia | N32: Yes | O32: Yes | X32: {=SUMPRODUCT(--(INDEX('1870 Bastrop Clean'!A:W, MATCH(A32 & "|" & B32,'1870 Bastrop Clean'!A:A & "|" & '1870 Bastrop Clean'!B:B, 0), 0) <> '1870 Bastrop Raw'!A32:W32))} -> 3
A33: 32 | B33: 7 | C33: 8 | D33: Spittler | E33: N M | F33: 37 | G33: 1833 | H33: Male | I33: White | J33: Farmer & Dik Co | K33: 1500 | L33: 500 | M33: Indiana | N33: Yes | V33: Yes | X33: {=SUMPRODUCT(--(INDEX('1870 Bastrop Clean'!A:W, MATCH(A33 & "|" & B33,'1870 Bastrop Clean'!A:A & "|" & '1870 Bastrop Clean'!B:B, 0), 0) <> '1870 Bastrop Raw'!A33:W33))} -> 0
A34: 33 | B34: 7 | C34: 8 | D34: Spittler | E34: Sarah | F34: 33 | G34: 1837 | H34: Female | I34: White | J34: Keeping House | M34: Texas | X34: {=SUMPRODUCT(--(INDEX('1870 Bastrop Clean'!A:W, MATCH(A34 & "|" & B34,'1870 Bastrop Clean'!A:A & "|" & '1870 Bastrop Clean'!B:B, 0), 0) <> '1870 Bastrop Raw'!A34:W34))} -> 0
A35: 34 | B35: 7 | C35: 8 | D35: Spittler | E35: Jos M | F35: 11 | G35: 1859 | H35: Male | I35: White | M35: Texas | R35: Yes | X35: {=SUMPRODUCT(--(INDEX('1870 Bastrop Clean'!A:W, MATCH(A35 & "|" & B35,'1870 Bastrop Clean'!A:A & "|" & '1870 Bastrop Clean'!B:B, 0), 0) <> '1870 Bastrop Raw'!A35:W35))} -> 0
A36: 35 | B36: 7 | C36: 8 | D36: Spittler | E36: Florence | F36: 9 | G36: 1861 | H36: Female | I36: White | M36: Texas | R36: Yes | X36: {=SUMPRODUCT(--(INDEX('1870 Bastrop Clean'!A:W, MATCH(A36 & "|" & B36,'1870 Bastrop Clean'!A:A & "|" & '1870 Bastrop Clean'!B:B, 0), 0) <> '1870 Bastrop Raw'!A36:W36))} -> 0
A37: 36 | B37: 7 | C37: 8 | D37: Spittler | E37: Allen | F37: 6 | G37: 1864 | H37: Male | I37: White | M37: Texas | X37: {=SUMPRODUCT(--(INDEX('1870 Bastrop Clean'!A:W, MATCH(A37 & "|" & B37,'1870 Bastrop Clean'!A:A & "|" & '1870 Bastrop Clean'!B:B, 0), 0) <> '1870 Bastrop Raw'!A37:W37))} -> 0
A38: 37 | B38: 7 | C38: 8 | D38: Spittler | E38: W M | F38: 2 | G38: 1868 | H38: Male | I38: White | M38: Texas | X38: {=SUMPRODUCT(--(INDEX('1870 Bastrop Clean'!A:W, MATCH(A38 & "|" & B38,'1870 Bastrop Clean'!A:A & "|" & '1870 Bastrop Clean'!B:B, 0), 0) <> '1870 Bastrop Raw'!A38:W38))} -> 0
A39: 38 | B39: 7 | C39: 8 | D39: Sneed | E39: Cyntah | F39: 35 | G39: 1835 | H39: Female | I39: Black | J39: Domestic Servant | M39: Georgia | S39: Yes | T39: Yes | X39: {=SUMPRODUCT(--(INDEX('1870 Bastrop Clean'!A:W, MATCH(A39 & "|" & B39,'1870 Bastrop Clean'!A:A & "|" & '1870 Bastrop Clean'!B:B, 0), 0) <> '1870 Bastrop Raw'!A39:W39))} -> 2
A40: 39 | B40: 7 | C40: 8 | D40: Wilkins | E40: Haney | F40: 53 | G40: 1817 | H40: Female | I40: Black | J40: Farm Laborer | M40: Alabama | S40: Yes | T40: Yes | X40: {=SUMPRODUCT(--(INDEX('1870 Bastrop Clean'!A:W, MATCH(A40 & "|" & B40,'1870 Bastrop Clean'!A:A & "|" & '1870 Bastrop Clean'!B:B, 0), 0) <> '1870 Bastrop Raw'!A40:W40))} -> 2
...

Sheet 1880 Bastrop 0008 Clean
A1: Line Number | B1: Dwelling Number | C1: Street | D1: Surname | E1: Given Name | F1: Race | G1: Gender | H1: Age | I1: Birth Month | J1: Birth Year | K1: Relation to Head of House | L1: Marital Status | M1: Married During Census Year | N1: Occupation | O1: Months Not Employed | P1: Sick | Q1: Blind | R1: Deaf and Dumb | S1: Idiotic | T1: Insane | U1: Maimed, Crippled, or Bedridden | V1: Attended School | W1: Cannot Read | X1: Cannot Write | Y1: Birthplace | Z1: Father's Birthplace | AA1: Mother's Birthplace
A2: 1 | B2: 1 | D2: Wertzner | E2: Charles | F2: White | G2: Male | H2: 57 | J2: Abt 1823 | K2: Self (Head) | L2: Married | N2: Merchant | Y2: Saxony | Z2: Saxony | AA2: Saxony
A3: 2 | B3: 1 | D3: Wertzner | E3: Fransisca | F3: White | G3: Female | H3: 42 | J3: Abt 1838 | K3: Wife | L3: Married | N3: Housekeeper | Y3: Bohemia | Z3: Bohemia | AA3: Bohemia
A4: 3 | B4: 1 | D4: Wertzner | E4: Selma | F4: White | G4: Female | H4: 17 | J4: Abt 1863 | K4: Daughter | L4: Single | Y4: Texas | Z4: Saxony | AA4: Bohemia
A5: 4 | B5: 1 | D5: Wertzner | E5: Pauline | F5: White | G5: Female | H5: 15 | J5: Abt 1865 | K5: Daughter | L5: Single | Y5: Texas | Z5: Saxony | AA5: Bohemia
A6: 5 | B6: 1 | D6: Wertzner | E6: Birtha | F6: White | G6: Female | H6: 11 | J6: Abt 1869 | K6: Daughter | L6: Single | Y6: Texas | Z6: Saxony | AA6: Bohemia
A7: 6 | B7: 1 | D7: Wertzner | E7: Louis | F7: White | G7: Male | H7: 9 | J7: Abt 1871 | K7: Son | L7: Single | Y7: Texas | Z7: Saxony | AA7: Bohemia
A8: 7 | B8: =B2 -> 1 | D8: Wertzner | E8: Juliana | F8: White | G8: Female | H8: 7 | J8: Abt 1873 | K8: Daughter | L8: Single | Y8: Texas | Z8: Saxony | AA8: Bohemia
A9: 8 | B9: =B3 -> 1 | D9: Wertzner | E9: Bruno | F9: White | G9: Male | H9: 5 | J9: Abt 1875 | K9: Son | L9: Single | Y9: Texas | Z9: Saxony | AA9: Bohemia
A10: 9 | B10: =B4 -> 1 | D10: Wertzner | E10: Hugo | F10: White | G10: Male | H10: 1 | J10: Abt 1879 | K10: Son | L10: Single | Y10: Texas | Z10: Saxony | AA10: Bohemia
A11: 10 | B11: =B5 -> 1 | D11: Brandt | E11: H. | F11: White | G11: Male | H11: 18 | J11: Abt 1862 | K11: Boarder | L11: Single | N11: Clerk in post office | Y11: Texas | Z11: Prussia | AA11: Prussia
A12: 11 | B12: =B6 -> 1 | D12: Ploger | E12: Gus | F12: White | G12: Male | H12: 19 | J12: Abt 1861 | K12: Boarder | L12: Single | N12: Clerk in store | Y12: Texas | Z12: Prussia | AA12: Hungary
A13: 12 | B13: =B7 -> 1 | D13: Zandon | E13: William | F13: White | G13: Male | H13: 21 | J13: Abt 1859 | K13: Boarder | L13: Single | N13: Clerk in store | Y13: Prussia | Z13: Prussia | AA13: Prussia
A14: 13 | B14: 2 | D14: Gell | E14: Robert | F14: White | G14: Male | H14: 35 | J14: Abt 1845 | K14: Self (Head) | L14: Married | N14: Merchant | Y14: Tennessee | Z14: Tennessee | AA14: Tennessee
A15: 14 | B15: 2 | D15: Gell | E15: Mary J. | F15: White | G15: Female | H15: 33 | J15: Abt 1847 | K15: Wife | L15: Married | N15: Housekeeper | Y15: England | Z15: England | AA15: England
A16: 15 | B16: 2 | D16: Gell | E16: Edner E. | F16: White | G16: Female | H16: 11 | J16: Abt 1869 | K16: Daughter | L16: Single | V16: Y | Y16: Texas | Z16: Tennessee | AA16: England
A17: 16 | B17: 2 | D17: Gell | E17: Robert L. | F17: White | G17: Male | H17: 8 | J17: Abt 1872 | K17: Son | L17: Single | V17: Y | Y17: Texas | Z17: Tennessee | AA17: England
A18: 17 | B18: 2 | D18: Smutfeld | E18: Olga | F18: White | G18: Female | H18: 14 | J18: Abt 1866 | K18: Servant | L18: Single | N18: Cook | Y18: Germany
A19: 18 | B19: 3 | D19: Vogt | E19: Charles | F19: White | G19: Male | H19: 42 | J19: Abt 1838 | K19: Self (Head) | L19: Married | N19: Gunsmith | Y19: Prussia | Z19: Prussia | AA19: Prussia
A20: 19 | B20: 3 | D20: Vogt | E20: Caroline | F20: White | G20: Female | H20: 32 | J20: Abt 1848 | K20: Wife | L20: Married | N20: Housekeeper | Y20: Bohemia | Z20: Bohemia | AA20: Bohemia
A21: 20 | B21: 3 | D21: Vogt | E21: Paul | F21: White | G21: Male | H21: 12 | J21: Abt 1868 | K21: Son | L21: Single | V21: Y | Y21: Texas | Z21: Prussia | AA21: Bohemia
A22: 21 | B22: 3 | D22: Vogt | E22: Anna | F22: White | G22: Female | H22: 9 | J22: Abt 1871 | K22: Daughter | L22: Single | Y22: Texas | Z22: Prussia | AA22: Bohemia
A23: 22 | B23: 3 | D23: Vogt | E23: Maxmilian | F23: White | G23: Male | H23: 7 | J23: Abt 1873 | K23: Son | L23: Single | Y23: Texas | Z23: Prussia | AA23: Bohemia
A24: 23 | B24: 3 | D24: Vogt | E24: Mary | F24: White | G24: Female | H24: 3 | J24: Abt 1877 | K24: Daughter | L24: Single | Y24: Texas | Z24: Prussia | AA24: Bohemia
A25: 24 | B25: 3 | D25: Vogt | E25: Ida | F25: White | G25: Female | H25: 45759 | I25: Feb | J25: Abt 1880 | K25: Daughter | L25: Single | Y25: Texas | Z25: Prussia | AA25: Bohemia
A26: 25 | B26: 4 | D26: Wiseman | E26: Louis | F26: White | G26: Male | H26: 60 | J26: Abt 1820 | K26: Self (Head) | L26: Married | N26: Watchmaker | Y26: Wurtemburg | Z26: Wurttemberg | AA26: Wurtemburg
A27: 26 | B27: 4 | D27: Wiseman | E27: Sophia | F27: White | G27: Female | H27: 57 | J27: Abt 1823 | K27: Wife | L27: Married | N27: Housekeeper | Y27: Hanover | Z27: Germany | AA27: Germany
A28: 27 | B28: 5 | D28: Pranse | E28: Reinhard | F28: White | G28: Male | H28: 39 | J28: Abt 1841 | K28: Self (Head) | L28: Married | N28: Furniture dealer | Y28: Selasia | Z28: Selasia | AA28: Texas
A29: 28 | B29: 5 | D29: Pranse | E29: Augusta | F29: White | G29: Female | H29: 30 | J29: Abt 1850 | K29: Wife | L29: Married | N29: Housekeeper | Y29: Texas | Z29: Selasia | AA29: Selasia
A30: 29 | B30: 5 | D30: Pranse | E30: Anna | F30: White | G30: Female | H30: 9 | J30: Abt 1871 | K30: Daughter | L30: Single | Y30: Texas | Z30: Selasia | AA30: Texas
A31: 30 | B31: 5 | D31: Pranse | E31: Albert | F31: White | G31: Male | H31: 7 | J31: Abt 1873 | K31: Son | L31: Single | Y31: Texas | Z31: Selasia | AA31: Texas
A32: 31 | B32: 5 | D32: Pranse | E32: Martha | F32: White | G32: Female | H32: 5 | J32: Abt 1875 | K32: Daughter | L32: Single | Y32: Texas | Z32: Selasia | AA32: Texas
A33: 32 | B33: 6 | D33: Walter | E33: William | F33: White | G33: Male | H33: 63 | J33: Abt 1817 | K33: Self (Head) | L33: Married | N33: Grocer and Baker | Y33: Prussia | Z33: Prussia | AA33: Prussia
A34: 33 | B34: 6 | D34: Walter | E34: Joanah | F34: White | G34: Female | H34: 60 | J34: Abt 1820 | K34: Wife | L34: Married | N34: Housekeeper | Y34: Prussia | Z34: Holstein | AA34: Holstein
A35: 34 | B35: 7 | D35: Prokoop | E35: M. A. | F35: White | G35: Male | H35: 47 | J35: Abt 1833 | K35: Self (Head) | L35: Married | N35: Shoemaker | Y35: Bohemia | Z35: Bohemia | AA35: Bohemia
A36: 35 | B36: 7 | D36: Prokoop | E36: Anna M. | F36: White | G36: Female | H36: 48 | J36: Abt 1832 | K36: Wife | L36: Married | N36: Housekeeper | Y36: Bohemia | Z36: Bohemia | AA36: Bohemia
A37: 36 | B37: 7 | D37: Prokoop | E37: Frank | F37: White | G37: Male | H37: 19 | J37: Abt 1861 | K37: Son | L37: Single | N37: Apprentice shoemaker | Y37: Texas | Z37: Bohemia | AA37: Bohemia
A38: 37 | B38: 7 | D38: Prokoop | E38: Emeil | F38: White | G38: Male | H38: 15 | J38: Abt 1865 | K38: Son | L38: Single | Y38: Texas | Z38: Bohemia | AA38: Bohemia
A39: 38 | B39: 8 | D39: Keslus | E39: William M. | F39: White | G39: Male | H39: 46 | J39: Abt 1834 | K39: Self (Head) | L39: Married | N39: Tailor | Y39: Prussia | Z39: Prussia | AA39: Prussia
A40: 39 | B40: 8 | D40: Keslus | E40: Anna | F40: White | G40: Female | H40: 30 | J40: Abt 1850 | K40: Wife | L40: Married | N40: Housekeeper | Y40: Bohemia | Z40: Bohemia | AA40: Bohemia
...

Sheet 1880 Bastrop 0008 Raw
A1: Line Number | B1: Dwelling Number | C1: Street | D1: Surname | E1: Given Name | F1: Race | G1: Gender | H1: Age | I1: Birth Month | J1: Birth Year | K1: Relation to Head of House | L1: Marital Status | M1: Married During Census Year | N1: Occupation | O1: Months Not Employed | P1: Sick | Q1: Blind | R1: Deaf and Dumb | S1: Idiotic | T1: Insane | U1: Maimed, Crippled, or Bedridden | V1: Attended School | W1: Cannot Read | X1: Cannot Write | Y1: Birthplace | Z1: Father's Birthplace | AA1: Mother's Birthplace | AC1: Comp.
A2: 1 | B2: 1 | D2: Wertzner | E2: Charles | F2: White | G2: Male | H2: 57 | J2: Abt 1823 | K2: Self (Head) | L2: Married | N2: Merchant | Y2: Saxony | Z2: Saxony | AA2: Saxony | AC2: {=SUMPRODUCT(--(INDEX('1880 Bastrop 0008 Clean'!A:AA, MATCH(A2 & "|" & B2, '1880 Bastrop 0008 Clean'!A:A & "|" & '1880 Bastrop 0008 Clean'!B:B, 0), 0) <> '1880 Bastrop 0008 Raw'!A2:AA2))} -> 0
A3: 2 | B3: 1 | D3: Wertzner | E3: Fransisca | F3: White | G3: Female | H3: 42 | J3: Abt 1838 | K3: Wife | L3: Married | N3: Housekeeper | Y3: Bohemia | Z3: Bohemia | AA3: Bohemia | AC3: {=SUMPRODUCT(--(INDEX('1880 Bastrop 0008 Clean'!A:AA, MATCH(A3 & "|" & B3, '1880 Bastrop 0008 Clean'!A:A & "|" & '1880 Bastrop 0008 Clean'!B:B, 0), 0) <> '1880 Bastrop 0008 Raw'!A3:AA3))} -> 0
A4: 3 | B4: 1 | D4: Wertzner | E4: Selma | F4: White | G4: Female | H4: 17 | J4: Abt 1863 | K4: Daughter | L4: Single | Y4: Texas | Z4: Saxony | AA4: Bohemia | AC4: {=SUMPRODUCT(--(INDEX('1880 Bastrop 0008 Clean'!A:AA, MATCH(A4 & "|" & B4, '1880 Bastrop 0008 Clean'!A:A & "|" & '1880 Bastrop 0008 Clean'!B:B, 0), 0) <> '1880 Bastrop 0008 Raw'!A4:AA4))} -> 0
A5: 4 | B5: 1 | D5: Wertzner | E5: Pauline | F5: White | G5: Female | H5: 15 | J5: Abt 1865 | K5: Daughter | L5: Single | Y5: Texas | Z5: Saxony | AA5: Bohemia | AC5: {=SUMPRODUCT(--(INDEX('1880 Bastrop 0008 Clean'!A:AA, MATCH(A5 & "|" & B5, '1880 Bastrop 0008 Clean'!A:A & "|" & '1880 Bastrop 0008 Clean'!B:B, 0), 0) <> '1880 Bastrop 0008 Raw'!A5:AA5))} -> 0
A6: 5 | B6: 1 | D6: Wertzner | E6: Bertha | F6: White | G6: Female | H6: 11 | J6: Abt 1869 | K6: Daughter | L6: Single | Y6: Texas | Z6: Saxony | AA6: Bohemia | AC6: {=SUMPRODUCT(--(INDEX('1880 Bastrop 0008 Clean'!A:AA, MATCH(A6 & "|" & B6, '1880 Bastrop 0008 Clean'!A:A & "|" & '1880 Bastrop 0008 Clean'!B:B, 0), 0) <> '1880 Bastrop 0008 Raw'!A6:AA6))} -> 1
A7: 6 | B7: 1 | D7: Wertzner | E7: Louis | F7: White | G7: Male | H7: 9 | J7: Abt 1871 | K7: Son | L7: Single | Y7: Texas | Z7: Saxony | AA7: Bohemia | AC7: {=SUMPRODUCT(--(INDEX('1880 Bastrop 0008 Clean'!A:AA, MATCH(A7 & "|" & B7, '1880 Bastrop 0008 Clean'!A:A & "|" & '1880 Bastrop 0008 Clean'!B:B, 0), 0) <> '1880 Bastrop 0008 Raw'!A7:AA7))} -> 0
A8: 7 | B8: 1 | D8: Wertzner | E8: Juliana | F8: White | G8: Female | H8: 7 | J8: Abt 1873 | K8: Daughter | L8: Single | Y8: Texas | Z8: Saxony | AA8: Bohemia | AC8: {=SUMPRODUCT(--(INDEX('1880 Bastrop 0008 Clean'!A:AA, MATCH(A8 & "|" & B8, '1880 Bastrop 0008 Clean'!A:A & "|" & '1880 Bastrop 0008 Clean'!B:B, 0), 0) <> '1880 Bastrop 0008 Raw'!A8:AA8))} -> 0
A9: 8 | B9: 1 | D9: Wertzner | E9: Bruno | F9: White | G9: Male | H9: 5 | J9: Abt 1875 | K9: Son | L9: Single | Y9: Texas | Z9: Saxony | AA9: Bohemia | AC9: {=SUMPRODUCT(--(INDEX('1880 Bastrop 0008 Clean'!A:AA, MATCH(A9 & "|" & B9, '1880 Bastrop 0008 Clean'!A:A & "|" & '1880 Bastrop 0008 Clean'!B:B, 0), 0) <> '1880 Bastrop 0008 Raw'!A9:AA9))} -> 0
A10: 9 | B10: 1 | D10: Wertzner | E10: Hugo | F10: White | G10: Male | H10: 1 | J10: Abt 1879 | K10: Son | L10: Single | Y10: Texas | Z10: Saxony | AA10: Bohemia | AC10: {=SUMPRODUCT(--(INDEX('1880 Bastrop 0008 Clean'!A:AA, MATCH(A10 & "|" & B10, '1880 Bastrop 0008 Clean'!A:A & "|" & '1880 Bastrop 0008 Clean'!B:B, 0), 0) <> '1880 Bastrop 0008 Raw'!A10:AA10))} -> 0
